Workbook

Sheet Resumo
A1: RESUMO POR CAPÍTULO
A2: Apartamento Contestável — Renovação | Maximinos, Braga
A4: Cap. | B4: Designação | C4: Valor (s/IVA)
A5: 1 | B5: DEMOLIÇÕES E TRABALHOS PREPARATÓRIOS | C5: =Orçamento!F6
A6: 2 | B6: TETOS FALSOS — GESSO CARTONADO | C6: =Orçamento!F12
A7: 3 | B7: PAVIMENTOS | C7: =Orçamento!F16
A8: 4 | B8: REVESTIMENTOS DE PAREDES | C8: =Orçamento!F20
A9: 5 | B9: COZINHA | C9: =Orçamento!F23
A10: 6 | B10: PORTAS INTERIORES | C10: =Orçamento!F27
A11: 7 | B11: INSTALAÇÕES SANITÁRIAS — LOUÇAS E EQUIPAMENTO | C11: =Orçamento!F31
A12: 8 | B12: PINTURA | C12: =Orçamento!F40
A13: 9 | B13: ARMÁRIOS E MÓVEIS POR MEDIDA | C13: =Orçamento!F42
A14: 10 | B14: INSTALAÇÃO ELÉTRICA E ILUMINAÇÃO | C14: =Orçamento!F46
A15: 11 | B15: CARPINTARIA | C15: =Orçamento!F49
A16: 12 | B16: SERRALHARIA | C16: =Orçamento!F51
B17: VALOR GLOBAL LÍQUIDO DA OBRA | C17: =SUM(C5:C16)
A19: Ver folha «Orçamento» para imprevistos, margem, IVA e total geral. Ver folha «Erros, Omissões e Melhorias» para trabalhos não contemplados.

Sheet Orçamento
A1: ORÇAMENTO DE OBRA DE RENOVAÇÃO
A2: Apartamento Contestável — Praça do Contestável, n.º 117, 8.º Piso, 4700-215 Maximinos, Braga
A3: Cliente: Rosário Calado | Projeto de Arquitetura: Diogo Barbosa, Arq.to | Data: junho 2026
A5: Ref. | B5: Descrição dos Trabalhos | C5: Qtd. | D5: Un. | E5: Preço Unit. | F5: Total
A6: 1. DEMOLIÇÕES E TRABALHOS PREPARATÓRIOS | E6: Subtotal | F6: =SUM(F7:F11)
A7: 1.1 | B7: Demolição de paredes interiores em alvenaria + remoção de entulho | C7: 35 | D7: m² | E7: 18 | F7: =C7*E7
A8: 1.2 | B8: Preparação e regularização de paramentos após demolições | C8: 1 | D8: vg | E8: 350 | F8: =C8*E8
A9: 1.3 | B9: Remoção do pavimento existente + remoção do entulho | C9: 100 | D9: m² | E9: 12 | F9: =C9*E9
A10: 1.4 | B10: Regularização do pavimento com betonilha autonivelante | C10: 100 | D10: m² | E10: 14 | F10: =C10*E10
A11: 1.5 | B11: Remoção dos rodapés existentes | C11: 300 | D11: ml | E11: 2.5 | F11: =C11*E11
A12: 2. TETOS FALSOS — GESSO CARTONADO | E12: Subtotal | F12: =SUM(F13:F15)
A13: 2.1 | B13: Estrutura metálica para teto falso + sancas (pronto a barrar) | C13: 100 | D13: m² | E13: 14 | F13: =C13*E13
A14: 2.2 | B14: Placa de gesso cartonado standard + emassamento (pronto a pintar) | C14: 80 | D14: m² | E14: 16 | F14: =C14*E14
A15: 2.3 | B15: Placa de gesso cartonado hidrófugo + emassamento (zonas húmidas) | C15: 20 | D15: m² | E15: 20 | F15: =C15*E15
A16: 3. PAVIMENTOS | E16: Subtotal | F16: =SUM(F17:F19)
A17: 3.1 | B17: Pavimento flutuante AC5 ou equivalente, incl. aplicação e base | C17: 85 | D17: m² | E17: 28 | F17: =C17*E17
A18: 3.2 | B18: Microcimento em pavimento de Instalações Sanitárias | C18: 10 | D18: m² | E18: 60 | F18: =C18*E18
A19: 3.3 | B19: Pavimento cerâmico (a definir) — fornecimento e assentamento | C19: 5 | D19: m² | E19: 45 | F19: =C19*E19
A20: 4. REVESTIMENTOS DE PAREDES | E20: Subtotal | F20: =SUM(F21:F22)
A21: 4.1 | B21: Microcimento em paredes de Instalações Sanitárias | C21: 50 | D21: m² | E21: 55 | F21: =C21*E21
A22: 4.2 | B22: Apainelados decorativos no Hall de entrada + Circulação | C22: 15 | D22: m² | E22: 90 | F22: =C22*E22
A23: 5. COZINHA | E23: Subtotal | F23: =SUM(F24:F26)
A24: 5.1 | B24: Móveis cozinha (inf.+sup.) lacados branco/bege, puxador oculto, 4,20 ml x 2,20 m | C24: 4.2 | D24: ml | E24: 950 | F24: =C24*E24
A25: 5.2 | B25: Móvel ilha de cozinha (1,80 x 0,60 m) | C25: 1 | D25: un | E25: 1800 | F25: =C25*E25
A26: 5.3 | B26: Bancada em silestone/dekton ou equivalente | C26: 7.5 | D26: m² | E26: 320 | F26: =C26*E26
A27: 6. PORTAS INTERIORES | E27: Subtotal | F27: =SUM(F28:F30)
A28: 6.1 | B28: Porta interior lacada branco/bege 0,80 x 2,20 m (fornecimento) | C28: 4 | D28: un | E28: 280 | F28: =C28*E28
A29: 6.2 | B29: Instalação, ferragens e acabamentos de portas | C29: 5 | D29: un | E29: 120 | F29: =C29*E29
A30: 6.3 | B30: Porta interior pivotante lacada branco/bege 1,10 x 2,20 m | C30: 1 | D30: un | E30: 750 | F30: =C30*E30
A31: 7. INSTALAÇÕES SANITÁRIAS — LOUÇAS E EQUIPAMENTO | E31: Subtotal | F31: =SUM(F32:F39)
A32: 7.1 | B32: Base de duche WC1 (0,70 x 0,70 m) | C32: 1 | D32: un | E32: 180 | F32: =C32*E32
A33: 7.2 | B33: Base de duche WC2 (0,80 x 1,80 m) | C33: 1 | D33: un | E33: 320 | F33: =C33*E33
A34: 7.3 | B34: Sanita de pousar | C34: 2 | D34: un | E34: 250 | F34: =C34*E34
A35: 7.4 | B35: Lavatório | C35: 2 | D35: un | E35: 180 | F35: =C35*E35
A36: 7.5 | B36: Torneiras e acessórios de lavatório | C36: 2 | D36: un | E36: 150 | F36: =C36*E36
A37: 7.6 | B37: Monocomando de duche | C37: 2 | D37: un | E37: 160 | F37: =C37*E37
A38: 7.7 | B38: Resguardo de duche WC1 (1,40 x 2,20 m) | C38: 1 | D38: un | E38: 450 | F38: =C38*E38
A39: 7.8 | B39: Resguardo de duche WC2 (1,00 x 2,20 m) | C39: 1 | D39: un | E39: 400 | F39: =C39*E39
A40: 8. PINTURA | E40: Subtotal | F40: =SUM(F41:F41)
A41: 8.1 | B41: Aplicação de primário + pintura final (paredes e tetos) | C41: 350 | D41: m² | E41: 8 | F41: =C41*E41
...

Sheet Erros, Omissões e Melhorias
A1: ERROS, OMISSÕES E MELHORIAS PROPOSTAS
A2: Análise técnica do Mapa de Quantidades — Apartamento Contestável
A4: A. ERROS E INCOERÊNCIAS DETETADAS NO MAPA DE QUANTIDADES
A5: # | B5: Ponto detetado | C5: Solução proposta
A6: A1 | B6: Numeração duplicada/errada: o capítulo PINTURA está numerado «7.1» (repete as IS) e a SERRALHARIA «11.1» (repete a CARPINTARIA). | C6: Renumerar de forma sequencial (PINTURA=8, ARMÁRIOS=9, ILUMINAÇÃO=10, CARPINTARIA=11, SERRALHARIA=12). Já corrigido na folha «Orçamento».
A7: A2 | B7: Itens sem quantidade nem preço: 9.1/9.2 Iluminação e tomadas (qtd «-») e 8.3 Móvel WC2 sem medição. | C7: Quantificar. No orçamento foram assumidos valores a forfait (vg) — a confirmar com medição/projeto de eletricidade.
A8: A3 | B8: Resguardo de duche desproporcional à base: WC1 tem base 0,70×0,70 m mas resguardo 1,40×2,20 m. | C8: Confirmar dimensão real do vão de duche; provável erro de cota da base ou do resguardo. Rever em obra.
A9: A4 | B9: Microcimento aparece em «Pavimentos» (3.2, 10 m²) e «Revestimentos» (4.1, 50 m²) — risco de dupla contagem se descrição não distinguir piso/parede. | C9: Manter separado (piso vs. parede) com referência clara; foi assim tratado no orçamento.
A10: A5 | B10: Incoerência de pé-direito entre plantas: estado atual PD 2,64–2,71 m; proposta 2,35–2,60 m (rebaixamento por teto falso) — sem mapa de áreas que confirme os 100 m² de teto. | C10: Validar áreas de teto vs. área útil (~110 m²); confirmar se 100 m² de estrutura cobrem toda a área ou só zonas com sanca.
A11: A6 | B11: Pavimento: demolição e autonivelante medidos a 100 m², mas revestimentos somam 85+10+5 = 100 m² — sem folga para áreas de armários/cozinha. | C11: Confirmar se pavimento sob roupeiros/cozinha é ou não revestido (poupança possível); ajustar medição.
A12: A7 | B12: Quantidade de pintura (350 m²) não tem mapa de cálculo de paredes+tetos que a suporte. | C12: Anexar medição de paredes e tetos; 350 m² parece coerente para ~110 m² úteis, mas deve ser justificado.
A14: B. OMISSÕES — TRABALHOS NÃO CONTEMPLADOS NO MTQ (provisão estimada)
A15: # | B15: Trabalho em falta | C15: Observação | D15: Estim. (s/IVA)
A16: B1 | B16: Estaleiro, montagem/desmontagem e instalações provisórias de obra | C16: Obrigatório; não consta do MTQ. | D16: 1500
A17: B2 | B17: Proteções de zonas comuns + meio de elevação (8.º piso: monta-cargas/elevador de obra) | C17: Crítico por ser 8.º andar — impacto logístico relevante. | D17: 2200
A18: B3 | B18: Transporte de entulho a vazadouro autorizado + taxas de deposição (RCD) e guias eletrónicas | C18: MTQ só refere «remoção»; falta transporte/taxas legais. | D18: 1200
A19: B4 | B19: Limpeza final de obra | C19: Não previsto. | D19: 600
A20: B5 | B20: Remodelação da rede de águas e esgotos (2 IS + cozinha + lavandaria) | C20: MTQ só tem louças; falta tubagem/ramais. | D20: 3500
A21: B6 | B21: Instalação elétrica completa: quadro novo, circuitos, certificação CERTIEL | C21: MTQ só refere tomadas/iluminação; falta infraestrutura e legalização. | D21: 3000
A22: B7 | B22: Ventilação/exaustão mecânica de IS e cozinha | C22: Obrigatório (RGEU/ventilação); não previsto. | D22: 1200
A23: B8 | B23: Impermeabilização das zonas húmidas (bases de duche e pavimentos de IS) | C23: Essencial antes de microcimento; não previsto. | D23: 800
A24: B9 | B24: Pré-instalação de climatização (AVAC / multi-split) | C24: Não previsto; recomendável definir antes dos tetos falsos. | D24: 3500
A25: B10 | B25: Lava-loiça, torneira de cozinha e pré-instalação de eletrodomésticos | C25: Cozinha sem loiça/ligações no MTQ. | D25: 900
A26: B11 | B26: Soleiras, peitoris e remates de vãos | C26: Não previsto. | D26: 600
A27: B12 | B27: Projeto de especialidades, telas finais, livro de obra e coordenação de segurança (CSO) | C27: Necessário se houver alteração de redes/comunicação à CM. | D27: 2500
... A29: B14 | B29: Eletrodomésticos (placa, forno, exaustor, frigorífico, máquinas) | C29: Opcional — a cargo do cliente? | D29: 0
A30: TOTAL PROVISÃO PARA OMISSÕES (a validar — não incluído no orçamento base) | D30: =SUM(D16:D29)
A32: C. SUGESTÕES E MELHORIAS
A33: # | B33: Sugestão | C33: Benefício
A34: C1 | B34: Definir já os acabamentos «a definir» (cerâmico 3.3, eletrodomésticos, loiças sanitárias modelo/marca) | C34: Evita erros e omissões e revisões de preço a meio da obra.
A35: C2 | B35: Optar por IVA reduzido a 6% (empreitada de reabilitação de habitação) em vez de 23% | C35: Poupança fiscal significativa (cumprindo requisitos legais do CIVA).
A36: C3 | B36: Incluir pré-instalação de climatização e cablagem de domótica/AV antes de fechar tetos falsos | C36: Muito mais barato agora do que abrir tetos no futuro.
A37: C4 | B37: Substituir vidro simples da divisória do hall por vidro duplo/laminado acústico | C37: Conforto acústico e segurança; pequeno acréscimo de custo.
A38: C5 | B38: Prever iluminação em circuitos/cenas (dimável) e ponto de carregamento USB nas IS/quartos | C38: Valoriza o imóvel com custo marginal baixo.
A39: C6 | B39: Calendarizar a obra com cronograma (Gantt) e plano de pagamentos por auto de medição | C39: Controlo de tesouraria e prazos; reduz risco de derrapagem.
A40: C7 | B40: Reavaliar revestir o pavimento sob roupeiros/cozinha (não visível) | C40: Poupança direta em material de pavimento.
A41: C8 | B41: Garantir base impermeabilizada + tela sob microcimento nas IS | C41: Previne patologias por humidade — o ponto fraco do microcimento.
